<?xml version="1.0" ?>
<!-- =================================================================================== -->
<!-- |    This document was autogenerated by xacro from artbot.xacro                   | -->
<!-- |    EDITING THIS FILE BY HAND IS NOT RECOMMENDED                                 | -->
<!-- =================================================================================== -->
<!-- Articulated (Revolute x3) Manipulator -->
<robot name="artbot" xmlns:xacro="http://www.ros.org/wiki/xacro">
  <!-- Constants for robot dimensions (in meters) -->
  <!-- Link 1, the stationary base -->
  <!-- Link 1 -->
  <!-- Link 1 -->
  <!-- Link 2, the rotating "shoulder" -->
  <!-- Link 2 -->
  <!-- Link 2 -->
  <!-- Link 3, the first arm section -->
  <!-- Link 3 -->
  <!-- Link 4, the second arm section -->
  <!-- Link 4 -->
  <!-- Constants for robot inertias (in kilograms) -->
  <!-- Link 2 -->
  <!-- Link 3 -->
  <!-- Link 4 -->
  <!-- Import all Gazebo-customization elements, including Gazebo colors -->
  <!-- ros_control plugin -->
  <gazebo>
    <plugin filename="libgazebo_ros_control.so" name="gazebo_ros_control">
      <robotNamespace>/artbot</robotNamespace>
      <robotSimType>gazebo_ros_control/DefaultRobotHWSim</robotSimType>
    </plugin>
  </gazebo>
  <!-- Link1 -->
  <gazebo reference="link1">
    <material>Gazebo/Grey</material>
  </gazebo>
  <!-- Link2 -->
  <gazebo reference="link2">
    <mu1>0.2</mu1>
    <mu2>0.2</mu2>
    <material>Gazebo/Blue</material>
  </gazebo>
  <!-- Link3 -->
  <gazebo reference="link3">
    <mu1>0.2</mu1>
    <mu2>0.2</mu2>
    <material>Gazebo/Orange</material>
  </gazebo>
  <!-- Link4 -->
  <gazebo reference="link4">
    <mu1>0.2</mu1>
    <mu2>0.2</mu2>
    <material>Gazebo/Blue</material>
  </gazebo>
  <!-- Import Rviz colors -->
  <material name="black">
    <color rgba="0.0 0.0 0.0 1.0"/>
  </material>
  <material name="blue">
    <color rgba="0.0 0.0 0.8 1.0"/>
  </material>
  <material name="green">
    <color rgba="0.0 0.8 0.0 1.0"/>
  </material>
  <material name="grey">
    <color rgba="0.2 0.2 0.2 1.0"/>
  </material>
  <material name="orange">
    <color rgba="1.0 0.423529411765 0.0392156862745 1.0"/>
  </material>
  <material name="brown">
    <color rgba="0.870588235294 0.811764705882 0.764705882353 1.0"/>
  </material>
  <material name="red">
    <color rgba="0.8 0.0 0.0 1.0"/>
  </material>
  <material name="white">
    <color rgba="1.0 1.0 1.0 1.0"/>
  </material>
  <!-- Used for fixing robot to Gazebo 'base_link' -->
  <link name="world"/>
  <joint name="fixed" type="fixed">
    <parent link="world"/>
    <child link="link1"/>
  </joint>
  <!-- Base Link -->
  <link name="link1">
    <collision>
      <origin rpy="0 0 0" xyz="0 0 0.08"/>
      <geometry>
        <box size="0.22 0.28 0.16"/>
      </geometry>
    </collision>
    <visual>
      <origin rpy="0 0 0" xyz="0 0 0.08"/>
      <geometry>
        <box size="0.22 0.28 0.16"/>
      </geometry>
      <material name="grey"/>
    </visual>
    <!-- Added visual element at base -->
    <visual>
      <origin rpy="0 0 0" xyz="0.11 0 0.08"/>
      <geometry>
        <cylinder length="0.16" radius="0.14"/>
      </geometry>
      <material name="grey"/>
    </visual>
    <!-- Inertial values unimportant for stationary base -->
    <inertial>
      <origin rpy="0 0 0" xyz="0 0 0.08"/>
      <mass value="1"/>
      <inertia ixx="1.0" ixy="0.0" ixz="0.0" iyy="1.0" iyz="0.0" izz="1.0"/>
    </inertial>
  </link>
  <joint name="joint1" type="continuous">
    <parent link="link1"/>
    <child link="link2"/>
    <origin rpy="0 0 0" xyz="0.11 0 0.16"/>
    <axis xyz="0 0 1"/>
    <dynamics damping="0.7"/>
  </joint>
  <!-- Shoulder Link -->
  <link name="link2">
    <collision>
      <origin rpy="0 0 0" xyz="0 0 0.0465"/>
      <geometry>
        <box size="0.198 0.348 0.093"/>
      </geometry>
    </collision>
    <visual>
      <origin rpy="0 0 0" xyz="0 0 0.0465"/>
      <geometry>
        <box size="0.198 0.348 0.093"/>
      </geometry>
      <material name="grey"/>
    </visual>
    <!-- Added visual elements at shoulder joint -->
    <!-- Shoulder cylinder 1 -->
    <visual>
      <origin rpy="1.57079632679 0 0" xyz="0 0.1044 0.186"/>
      <geometry>
        <cylinder length="0.087" radius="0.0837"/>
      </geometry>
      <material name="grey"/>
    </visual>
    <!-- Shoulder rectangle 1 -->
    <visual>
      <origin rpy="0 0 0" xyz="0 0.1044 0.093"/>
      <geometry>
        <box size="0.1782 0.1044 0.186"/>
      </geometry>
      <material name="grey"/>
    </visual>
    <!-- Shoulder rotation -->
    <!--
    <visual>
      <origin xyz="0 0 ${height2}" rpy="${PI/2} 0 0"/>
      <geometry>
	<cylinder length="${0.5*width2}" radius="${radius3}"/>
      </geometry>
      <material name="blue"/>
    </visual>
  -->
    <!-- Shoulder cylinder 2 -->
    <visual>
      <origin rpy="1.57079632679 0 0" xyz="0 -0.1044 0.186"/>
      <geometry>
        <cylinder length="0.087" radius="0.0837"/>
      </geometry>
      <material name="grey"/>
    </visual>
    <!-- Shoulder rectangle 2 -->
    <visual>
      <origin rpy="0 0 0" xyz="0 -0.1044 0.093"/>
      <geometry>
        <box size="0.1782 0.1044 0.186"/>
      </geometry>
      <material name="grey"/>
    </visual>
    <!-- Shoulder base cylinder -->
    <visual>
      <origin rpy="0 0 0" xyz="0 0 0.0465"/>
      <geometry>
        <cylinder length="0.093" radius="0.14"/>
      </geometry>
      <material name="grey"/>
    </visual>
    <!-- Simplified inertia of "shoulder" assuming solid uniform box -->
    <inertial>
      <origin rpy="0 0 0" xyz="0 0 0.093"/>
      <mass value="13.2423"/>
      <inertia ixx="0.1718188425" ixy="0.0" ixz="0.0" iyy="0.081440145" iyz="0.0" izz="0.1769038857"/>
    </inertial>
  </link>
  <joint name="joint2" type="continuous">
    <parent link="link2"/>
    <child link="link3"/>
    <origin rpy="0 0 0" xyz="0 0 0.186"/>
    <axis xyz="0 1 0"/>
    <dynamics damping="0.7"/>
  </joint>
  <!-- First Arm Section Link -->
  <link name="link3">
    <collision>
      <origin rpy="0 0 0" xyz="0 0 0.275"/>
      <geometry>
        <cylinder length="0.461" radius="0.0445"/>
      </geometry>
    </collision>
    <visual>
      <origin rpy="0 0 0" xyz="0 0 0.275"/>
      <geometry>
        <cylinder length="0.55" radius="0.0445"/>
      </geometry>
      <material name="grey"/>
    </visual>
    <!-- Added visual elements at second joint -->
    <!-- Shoulder rotation -->
    <visual>
      <origin rpy="1.57079632679 0 0" xyz="0 0 0"/>
      <geometry>
        <cylinder length="0.174" radius="0.0445"/>
      </geometry>
      <material name="blue"/>
    </visual>
    <!-- Simplified inertia of first arm cylinder, assuming a narrow rod -->
    <inertial>
      <origin rpy="0 0 0" xyz="0 0 0.275"/>
      <mass value="2.206"/>
      <inertia ixx="0.0556095833333" ixy="0.0" ixz="0.0" iyy="0.0" iyz="0.0" izz="0.0556095833333"/>
    </inertial>
  </link>
  <joint name="joint3" type="continuous">
    <parent link="link3"/>
    <child link="link4"/>
    <origin rpy="0 0 0" xyz="0 0 0.55"/>
    <axis xyz="0 1 0"/>
    <dynamics damping="0.7"/>
  </joint>
  <!-- Second Arm Section Link -->
  <link name="link4">
    <collision>
      <origin rpy="0 0 0" xyz="0 0 0.225"/>
      <geometry>
        <cylinder length="0.361" radius="0.0445"/>
      </geometry>
    </collision>
    <visual>
      <origin rpy="0 0 0" xyz="0 0 0.225"/>
      <geometry>
        <cylinder length="0.45" radius="0.0445"/>
      </geometry>
      <material name="grey"/>
    </visual>
    <!-- Added visual elements at third joint -->
    <!-- Shoulder rotation -->
    <visual>
      <origin rpy="1.57079632679 0 0" xyz="0 0 0"/>
      <geometry>
        <cylinder length="0.089" radius="0.0445"/>
      </geometry>
      <material name="blue"/>
    </visual>
    <!-- Simplified inertia of second arm cylinder, assuming a narrow rod -->
    <inertial>
      <origin rpy="0 0 0" xyz="0 0 0.225"/>
      <mass value="3.9638"/>
      <inertia ixx="0.066889125" ixy="0.0" ixz="0.0" iyy="1.0" iyz="0.0" izz="0.066889125"/>
    </inertial>
  </link>
  <transmission name="tran1">
    <type>transmission_interface/SimpleTransmission</type>
    <joint name="joint1">
      <hardwareInterface>EffortJointInterface</hardwareInterface>
    </joint>
    <actuator name="motor1">
      <hardwareInterface>EffortJointInterface</hardwareInterface>
      <mechanicalReduction>1</mechanicalReduction>
    </actuator>
  </transmission>
  <transmission name="tran2">
    <type>transmission_interface/SimpleTransmission</type>
    <joint name="joint2">
      <hardwareInterface>EffortJointInterface</hardwareInterface>
    </joint>
    <actuator name="motor2">
      <hardwareInterface>EffortJointInterface</hardwareInterface>
      <mechanicalReduction>1</mechanicalReduction>
    </actuator>
  </transmission>
  <transmission name="tran3">
    <type>transmission_interface/SimpleTransmission</type>
    <joint name="joint3">
      <hardwareInterface>EffortJointInterface</hardwareInterface>
    </joint>
    <actuator name="motor3">
      <hardwareInterface>EffortJointInterface</hardwareInterface>
      <mechanicalReduction>1</mechanicalReduction>
    </actuator>
  </transmission>
</robot>

